Workbook

Sheet Programs
A1: source_id | B1: nation_or_program | C1: state | D1: scope | E1: list_name | F1: list_type | G1: priority_class | H1: processing_status | I1: acquisition_mode | J1: format | K1: scrape_grade | L1: automation_score | M1: refresh_cadence | N1: approx_records | O1: authority | P1: rule_confidence | Q1: directory_url | R1: last_checked
A2: TBD-165 | B2: Alaska Native Village Corporation Association | C2: AK | D2: regional | E2: ANVCA Member Village Corporations | F2: ANC association membership | G2: Coverage Frame | H2: Complementary | I2: Crawl membership page for entity enumeration | J2: HTML | K2: C | L2: 2 | M2: Quarterly | O2: Alaska Native Village Corporation Association | P2: High | Q2: https://anvca.biz/ | R2: 2026-08-27
A3: TBD-164 | B3: Oklahoma Department of Commerce | C3: OK | D3: regional | E3: Minority Business Certification Programs: Oklahoma TERO Program Enumeration | F3: State TERO coverage index | G3: Coverage Frame | H3: Complementary | I3: Periodic PDF pull for program enumeration | J3: PDF | K3: C | L3: 2 | M3: Quarterly | O3: Oklahoma Department of Commerce | P3: High | Q3: https://www.okcommerce.gov/wp-content/uploads/Minority-Business-Certification-Programs.pdf | R3: 2026-08-27
A4: TBD-163 | B4: Council for Tribal Employment Rights | C4: US | D4: national | E4: CTER National TERO Program Coverage Frame | F4: National TERO umbrella organization | G4: Coverage Frame | H4: Complementary | I4: Crawl for TERO program enumeration and hosted documents | J4: HTML plus hosted PDFs | K4: C | L4: 2 | M4: Quarterly | O4: Council for Tribal Employment Rights | P4: High | Q4: https://cter-tero.org/ | R4: 2026-08-27
A5: TBD-162 | B5: Washington Office of Minority and Women’s Business Enterprises | C5: WA | D5: regional | E5: OMWBE Certified Businesses Directory: Native American Categories | F5: State certified-vendor directory | G5: Cross-Reference | H5: Complementary | I5: Directory query filtered to Native categories; monthly XLSX deltas | J5: Dynamic ASP directory plus monthly XLSX | K5: B | L5: 3 | M5: Monthly | O5: Washington State Office of Minority and Women’s Business Enterprises | P5: High | Q5: https://omwbe.diversitycompliance.com/FrontEnd/SearchCertifiedDirectory.asp | R5: 2026-08-27
A6: TBD-144 | B6: South Dakota Department of Transportation | C6: SD | D6: regional | E6: South Dakota Tribal TERO Compliance Resource Index | F6: Coverage frame | G6: Coverage Frame | H6: Complementary | I6: Landing-page and link-index scrape | J6: HTML plus linked PDFs | K6: A | L6: 4 | M6: Quarterly | O6: South Dakota Department of Transportation | P6: High | Q6: https://dot.sd.gov/programs-services/civil-rights/tribal-relations-tero/ | R6: 2026-08-27
A7: TBD-143 | B7: Minnesota Department of Transportation | C7: MN | D7: regional | E7: Minnesota Tribal Employment Rights Office Coverage Frame | F7: Coverage frame | G7: Coverage Frame | H7: Complementary | I7: Structured reference scrape | J7: HTML | K7: A | L7: 4 | M7: Quarterly | N7: 11 tribal contacts | O7: Minnesota Department of Transportation | P7: High | Q7: https://www.dot.state.mn.us/civilrights/tribal-employment-rights-offices.html | R7: 2026-08-27
A8: TBD-072 | B8: Bureau of Indian Affairs | C8: National | D8: national | E8: Tribal Leaders Directory | F8: Coverage frame | G8: Coverage Frame | H8: Complementary | I8: Direct download | J8: HTML plus CSV/XLSX | K8: A+ | L8: 5 | M8: Monthly | N8: 575 tribes (2026 listing) | O8: U.S. Bureau of Indian Affairs | P8: High | Q8: https://www.bia.gov/service/tribal-leaders-directory | R8: 2026-08-27
A9: TBD-152 | B9: American Indian Chamber of Commerce of Arizona | C9: AZ | D9: regional | E9: AICCAZ Members Directory | F9: Regional chamber directory | G9: Cross-Reference | H9: Complementary | I9: Browser-assisted crawl or embedded endpoint discovery | J9: Dynamic MembershipWorks directory | K9: C | L9: 2 | M9: Monthly | O9: American Indian Chamber of Commerce of Arizona | P9: High | Q9: https://www.aiccaz.com/members-directory-page | R9: 2026-08-27
A10: TBD-148 | B10: Minnesota Indigenous Business Alliance | C10: MN | D10: regional | E10: Buy Native Biz Directory | F10: Regional and national Native-business directory | G10: Cross-Reference | H10: Complementary | I10: Endpoint discovery or browser-assisted crawl | J10: Dynamic web directory | K10: C | L10: 2 | M10: Monthly | O10: Minnesota Indigenous Business Alliance | P10: Medium | Q10: https://directory.mniba.org/ | R10: 2026-08-27
A11: TBD-017 | B11: Sault Tribe Business Alliance | C11: MI | D11: single_nation | E11: Business Directory | F11: Cross-tribal directory | G11: Cross-Reference | H11: Complementary | I11: Dynamic DOM scrape | J11: Dynamic web directory | K11: C | L11: 2 | M11: Monthly | O11: Tribal-affiliated nonprofit/chamber | P11: Medium | Q11: https://www.stballiance.org/directory | R11: 2026-08-27
A12: TBD-155 | B12: Montana Department of Commerce | C12: MT | D12: regional | E12: Native American Made in Montana Product Directory | F12: State product and producer directory | G12: Cross-Reference | H12: Complementary | I12: Filter-aware directory scrape | J12: Searchable state directory | K12: B | L12: 3 | M12: Quarterly | O12: Montana Department of Commerce | P12: High | Q12: https://commerce.mt.gov/Business/Programs-and-Services/Made-in-Montana/Products | R12: 2026-08-27
A13: TBD-154 | B13: Rocky Mountain Indian Chamber of Commerce | C13: CO / Rocky Mountain | D13: regional | E13: RMICC Member List | F13: Regional chamber directory | G13: Cross-Reference | H13: Complementary | I13: DOM scrape | J13: HTML member/sponsor list | K13: B | L13: 3 | M13: Quarterly | O13: Rocky Mountain Indian Chamber of Commerce | P13: Medium | Q13: https://rmicc.org/ | R13: 2026-08-27
A14: TBD-153 | B14: American Indian Chamber of Commerce of Oklahoma | C14: OK | D14: regional | E14: AICCO Member Directory | F14: Statewide chamber directory | G14: Cross-Reference | H14: Complementary | I14: Pagination/API discovery | J14: GrowthZone directory | K14: B | L14: 3 | M14: Monthly | O14: American Indian Chamber of Commerce of Oklahoma | P14: High | Q14: https://business.aiccok.org/directory | R14: 2026-08-27
A15: TBD-151 | B15: Northwest Native Chamber | C15: OR / WA / Northwest | D15: regional | E15: Native Member Directory | F15: Regional Native-member directory | G15: Cross-Reference | H15: Complementary | I15: Endpoint discovery plus profile crawl | J15: Dynamic map and profile pages | K15: B | L15: 3 | M15: Monthly | O15: Northwest Native Chamber | P15: High | Q15: https://nwnc.org/native-member-directory/ | R15: 2026-08-27
A16: TBD-147 | B16: Native American Community Development Institute | C16: MN | D16: regional | E16: NACDI Indigenous Resource Directory | F16: Regional resource and business directory | G16: Cross-Reference | H16: Complementary | I16: Filter-aware DOM scrape | J16: Filterable HTML directory | K16: B | L16: 3 | M16: Monthly | O16: Native American Community Development Institute | P16: High | Q16: https://nacdi.org/directory/ | R16: 2026-08-27
A17: TBD-146 | B17: Minnesota American Indian Chamber of Commerce | C17: MN | D17: regional | E17: MAICC Member Directory | F17: Regional chamber directory | G17: Cross-Reference | H17: Complementary | I17: DOM scrape or directory endpoint discovery | J17: Dynamic member directory | K17: B | L17: 3 | M17: Monthly | O17: Minnesota American Indian Chamber of Commerce | P17: High | Q17: https://maicc.org/directory/ | R17: 2026-08-27
A18: TBD-071 | B18: Washington Native American Chamber of Commerce | C18: WA | D18: regional | E18: Member Business Directory | F18: Cross-tribal directory | G18: Cross-Reference | H18: Complementary | I18: Directory scrape after endpoint verification | J18: Web directory / membership site | K18: B | L18: 3 | M18: Quarterly | O18: Native chamber of commerce | P18: High | Q18: https://www.wnacc.org/ | R18: 2026-08-27
A19: TBD-069 | B19: American Indigenous Business Leaders | C19: National | D19: national | E19: Business Directory | F19: Cross-tribal directory | G19: Cross-Reference | H19: Complementary | I19: DOM scrape/API discovery | J19: Web directory | K19: B | L19: 3 | M19: Quarterly | O19: Native nonprofit | P19: Medium | Q19: https://aibl.org/business-directory/ | R19: 2026-08-27
A20: TBD-067 | B20: Washington Native Business Center | C20: WA | D20: regional | E20: Native Business Directory | F20: Cross-tribal directory | G20: Cross-Reference | H20: Complementary | I20: DOM scrape/API discovery | J20: Web directory | K20: B | L20: 3 | M20: Monthly | O20: Native business-support organization | P20: Medium | Q20: https://nativebusinesscenter.com/business-directory/ | R20: 2026-08-27
A21: TBD-066 | B21: Bureau of Indian Affairs / Buy Indian | C21: National | D21: national | E21: Buy Indian Native Vendor Resources / SAM Vendors | F21: Cross-tribal directory | G21: Cross-Reference | H21: Complementary | I21: API/data join | J21: HTML plus external procurement systems | K21: B | L21: 3 | M21: Monthly | O21: U.S. Department of the Interior / BIA | P21: Medium | Q21: https://www.bia.gov/as-ia/ocfo/buy-indian-act-info | R21: 2026-08-27
A22: TBD-065 | B22: Minneapolis Fed / Center for Indian Country Development | C22: National | D22: national | E22: Native Entity Enterprise Dataset (NEED) | F22: Government-owned enterprise dataset | G22: Cross-Reference | H22: Complementary | I22: Download or request dataset | J22: Dataset / research page | K22: B | L22: 3 | M22: Annual | N22: 5,559 establishments / 344 tribes | O22: Federal Reserve Bank of Minneapolis | P22: High | Q22: https://www.minneapolisfed.org/article/2025/new-data-showcase-the-breadth-of-tribally-owned-businesses | R22: 2026-08-27
A23: TBD-156 | B23: Colorado Department of Agriculture / Colorado Proud | C23: CO | D23: regional | E23: Native American-Owned Food and Agriculture Businesses | F23: State sector directory | G23: Cross-Reference | H23: Complementary | I23: Static DOM scrape | J23: HTML profiles/list | K23: A | L23: 4 | M23: Quarterly | O23: Colorado Department of Agriculture | P23: Medium | Q23: https://coloradoproud.com/nativeowned/ | R23: 2026-08-27
A24: TBD-150 | B24: American Indian Chamber of Commerce of New Mexico | C24: NM | D24: regional | E24: AICCNM Member Directory | F24: Regional chamber directory | G24: Cross-Reference | H24: Complementary | I24: Static DOM scrape | J24: Long-form HTML directory | K24: A | L24: 4 | M24: Monthly | O24: American Indian Chamber of Commerce of New Mexico | P24: High | Q24: https://www.aiccnm.com/member-directory | R24: 2026-08-27
A25: TBD-149 | B25: Wisconsin & Midwest Native Entrepreneurs Directory | C25: WI / Midwest | D25: regional | E25: Native Biz Directory | F25: Regional Native-owned business directory | G25: Cross-Reference | H25: Complementary | I25: Static or category-aware DOM scrape | J25: HTML directory | K25: A | L25: 4 | M25: Monthly | N25: 100+ | O25: Wisconsin Indigenous economic-development initiative | P25: Medium | Q25: https://nativebizdirectory.com/index.html | R25: 2026-08-27
A26: TBD-070 | B26: First Peoples Fund | C26: National | D26: national | E26: Artist Directory | F26: Artist directory | G26: Cross-Reference | H26: Complementary | I26: Directory scrape | J26: HTML | K26: A | L26: 4 | M26: Quarterly | O26: Native nonprofit | P26: Medium | Q26: https://www.firstpeoplesfund.org/about/artists-directory | R26: 2026-08-27
A27: TBD-068 | B27: Texas Native Health | C27: TX | D27: regional | E27: Native-Owned Business Directory | F27: Cross-tribal directory | G27: Cross-Reference | H27: Complementary | I27: Static/dynamic DOM scrape | J27: HTML | K27: A | L27: 4 | M27: Quarterly | O27: Native nonprofit | P27: Medium | Q27: https://texasnativehealth.org/native-owned-business-directory/ | R27: 2026-08-27
A28: TBD-064 | B28: United South and Eastern Tribes | C28: Regional | D28: regional | E28: Tribal Enterprise Directory | F28: Cross-tribal directory | G28: Cross-Reference | H28: Complementary | I28: Directory scrape | J28: HTML / directory | K28: A | L28: 4 | M28: Quarterly | N28: 600+ | O28: USET Sovereignty Protection Fund | P28: High | Q28: https://www.usetinc.org/departments/economic-development/tribal-enterprise-directory/ | R28: 2026-08-27
A29: TBD-063 | B29: U.S. Indian Arts and Crafts Board | C29: National | D29: national | E29: Source Directory of American Indian and Alaska Native Owned and Operated Arts and Crafts Businesses | F29: Cross-tribal directory | G29: Cross-Reference | H29: Complementary | I29: Structured directory scrape | J29: HTML / directory | K29: A | L29: 4 | M29: Quarterly | N29: 500+ | O29: U.S. Department of the Interior | P29: High | Q29: https://www.doi.gov/iacb/source-directory-arts-and-crafts-businesses | R29: 2026-08-27
A30: TBD-145 | B30: Minnesota Office of State Procurement | C30: MN | D30: regional | E30: TG/ED/VO Certified Vendor Directory: Indigenous American Category | F30: State certified-vendor directory | G30: Cross-Reference | H30: Complementary | I30: Direct CSV download filtered to category I | J30: Searchable HTML plus CSV | K30: A+ | L30: 5 | M30: Monthly | O30: State of Minnesota Department of Administration | P30: High | Q30: https://mn.gov/admin/osp/about-us/state-government/procuregoodsandgeneralservices/tgedvo-directory/ | R30: 2026-08-27
A31: TBD-028 | B31: Keweenaw Bay Indian Community | C31: MI | D31: single_nation | E31: Tribal Member-Owned Business Directory | F31: Member-owned directory | G31: Tribal Secondary | H31: Historical | I31: Historical archive parse; contact program | J31: PDF newsletter | K31: D | L31: 1 | M31: Annual | O31: Official tribal newsletter | P31: High | Q31: https://www.kbic-nsn.gov/wp-content/uploads/2025/03/September2004.pdf | R31: 2026-08-28
A32: TBD-027 | B32: Catawba Nation | C32: SC | D32: single_nation | E32: Tribal Member Owned Businesses Directory | F32: Member-owned directory | G32: Tribal Secondary | H32: Historical | I32: Monitor/search; contact economic development | J32: Unknown | K32: D | L32: 1 | M32: Semiannual | O32: Historical official/state reference | P32: Low | Q32: https://www.catawba.com/ | R32: 2026-08-27
A33: TBD-020 | B33: Citizen Potawatomi Nation | C33: OK | D33: single_nation | E33: Tribal Member Businesses | F33: Member-owned directory | G33: Tribal Secondary | H33: Historical | I33: Image archive plus manual extraction | J33: Image / redirect | K33: C | L33: 2 | M33: Semiannual | O33: Official tribal news | P33: Low | Q33: https://cpn.news/business | R33: 2026-08-27
A34: TBD-178 | B34: Tanana Chiefs Conference (Interior Alaska regional consortium) | C34: AK | D34: regional | E34: TCC TERO Indian-owned vendor listing (42 member villages) | F34: Consortium TERO / certified procurement | G34: Tribal Partnership | H34: Lead | I34: Request directly from TCC TERO | J34: Program page; list not posted | K34: D | L34: 1 | M34: Quarterly | O34: Tanana Chiefs Conference TERO | P34: Medium | Q34: https://www.tananachiefs.org/services/job-training/tero/ | R34: 2026-08-28
A35: TBD-167 | B35: Nisqually Indian Tribe | C35: WA | D35: single_nation | E35: Nisqually NAOB Registry (TERO certified Native American Owned Businesses) | F35: TERO / certified procurement | G35: Tribal Partnership | H35: Lead | I35: Request directly from TERO | J35: PDF references; list not posted | K35: D | L35: 1 | M35: Quarterly | O35: Nisqually TERO | P35: Medium | Q35: http://www.nisqually-nsn.gov/files/4716/2388/4801/TERO_Orientation.pdf | R35: 2026-08-27
A36: TBD-161 | B36: American Indian Chamber of Commerce of California | C36: CA | D36: regional | E36: AICCCAL Member Businesses | F36: Regional chamber directory | G36: Cross-Reference | H36: Lead | I36: Confirm directory access, then crawl | J36: HTML organization site | K36: D | L36: 1 | M36: Quarterly | O36: American Indian Chamber of Commerce of California | P36: High | Q36: https://aicccal.org/ | R36: 2026-08-27
A37: TBD-121 | B37: Squaxin Island Tribe | C37: WA | D37: single_nation | E37: Contractor Registry | F37: Mixed contractor registry | G37: Discovery Only | H37: Lead | I37: Request export or monitor directory publication | J37: HTML plus online form | K37: D | L37: 1 | M37: Semiannual | O37: Official Squaxin Island Tribe | P37: High | Q37: https://squaxinisland.org/contractor-registration/ | R37: 2026-08-27
A38: TBD-160 | B38: Osage Nation | C38: OK | D38: single_nation | E38: Tax Commission Registered Vendor Records | F38: Tribal vendor registration | G38: Tribal Partnership | H38: Lead | I38: Partnership request | J38: HTML plus PDF application packet | K38: D | L38: 1 | M38: Quarterly | O38: Official Osage Nation | P38: Medium | Q38: https://www.osagenation-nsn.gov/business | R38: 2026-08-27
A39: TBD-159 | B39: Turtle Mountain Band of Chippewa Indians | C39: ND | D39: single_nation | E39: TERO Indian-Owned Business Certifications | F39: TERO / certified procurement | G39: Tribal Partnership | H39: Lead | I39: Partnership request | J39: HTML tribal code | K39: D | L39: 1 | M39: Quarterly | O39: Official Turtle Mountain Band tribal code | P39: High | Q39: https://www.narf.org/nill/triballaw/us/nsn/tmchippewa/council/code/32.02.010/ | R39: 2026-08-27
A40: TBD-158 | B40: Pascua Yaqui Tribe | C40: AZ | D40: single_nation | E40: TERO Indian Enterprise Qualification Records | F40: TERO / certified procurement | G40: Tribal Partnership | H40: Lead | I40: Partnership request | J40: HTML plus PDF forms | K40: D | L40: 1 | M40: Quarterly | O40: Official Pascua Yaqui Tribe TERO | P40: Medium | Q40: https://www.pascuayaqui-nsn.gov/development-services/tero/ | R40: 2026-08-28
...

Sheet Summary
A1: Tribal Business List Programs — processing summary
A2: Derived from cedar_source_registry/sources.jsonl, wave 5, generated 2026-08-28. One row per source program in the Programs sheet; counts below are formulas over that sheet.
A4: Total programs tracked | B4: =COUNTA(Programs!A2:A175) -> 174
A6: By processing status
A7: Live | B7: =COUNTIF(Programs!H2:H175,"Live") -> 75
A8: Lead | B8: =COUNTIF(Programs!H2:H175,"Lead") -> 56
A9: Complementary | B9: =COUNTIF(Programs!H2:H175,"Complementary") -> 29
A10: Stale | B10: =COUNTIF(Programs!H2:H175,"Stale") -> 10
A11: Historical | B11: =COUNTIF(Programs!H2:H175,"Historical") -> 3
A12: Obtained | B12: =COUNTIF(Programs!H2:H175,"Obtained") -> 1
A14: By priority class
A15: Tribal Primary | B15: =COUNTIF(Programs!G2:G175,"Tribal Primary") -> 48
A16: Tribal Secondary | B16: =COUNTIF(Programs!G2:G175,"Tribal Secondary") -> 21
A17: Tribal Partnership | B17: =COUNTIF(Programs!G2:G175,"Tribal Partnership") -> 53
A18: Cross-Reference | B18: =COUNTIF(Programs!G2:G175,"Cross-Reference") -> 40
A19: Discovery Only | B19: =COUNTIF(Programs!G2:G175,"Discovery Only") -> 6
A20: Coverage Frame | B20: =COUNTIF(Programs!G2:G175,"Coverage Frame") -> 6
A22: By list type (top groups)
A23: TERO / certified procurement | B23: =COUNTIF(Programs!F2:F175,"TERO / certified procurement") -> 68
A24: Member-owned directory | B24: =COUNTIF(Programs!F2:F175,"Member-owned directory") -> 22
A25: Cross-tribal directory | B25: =COUNTIF(Programs!F2:F175,"Cross-tribal directory") -> 8
A26: Alaska Native corporation shareholder directory | B26: =COUNTIF(Programs!F2:F175,"Alaska Native corporation shareholder directory") -> 7
A27: Regional chamber directory | B27: =COUNTIF(Programs!F2:F175,"Regional chamber directory") -> 5
A28: Artist directory | B28: =COUNTIF(Programs!F2:F175,"Artist directory") -> 4
A30: Known list sizes (where a program reports one)
A31: Programs reporting a record count | B31: =COUNT(Programs!N2:N175) -> 9
A32: Sum of reported records | B32: =SUM(Programs!N2:N175) -> 181
A34: Source: Cedar Press source registry (public program metadata only; no business or personal records). Assembled by Lumecon; per-program authority is each nation's own office.
